Workbook

Sheet README
A1: Resource & Planning Dashboard Workbook (Template v2)
A3: Fill the input tabs (Projects, Engineers, Planned_ProjectMonth, Planned_Allocations, Actual_Hours, Skills, Lab_Tech_Hours, Milestones). Dashboard visuals update from those tables.
A5: Selectors: Use Params to choose SelectedMonth and SelectedProject. Optional: add Excel Form Control sliders and link them to Params cells.

Sheet Months
A1: Month | B1: MonthIndex | C1: MonthLabel
A2: 46023 | B2: 1 | C2: 2026-01
A3: 46054 | B3: 2 | C3: 2026-02
A4: 46082 | B4: 3 | C4: 2026-03
A5: 46113 | B5: 4 | C5: 2026-04
A6: 46143 | B6: 5 | C6: 2026-05
A7: 46174 | B7: 6 | C7: 2026-06
A8: 46204 | B8: 7 | C8: 2026-07
A9: 46235 | B9: 8 | C9: 2026-08
A10: 46266 | B10: 9 | C10: 2026-09
A11: 46296 | B11: 10 | C11: 2026-10
A12: 46327 | B12: 11 | C12: 2026-11
A13: 46357 | B13: 12 | C13: 2026-12

Sheet Projects
A1: ProjectID | B1: ProjectName | C1: Type | D1: WorkClass
A2: R1337.1 | B2: K4.0 Resi Concealed Sidewall | C2: NPD | D2: Planned
A3: R1337.3 | B3: K5.6 Resi Concealed Sidewall | C3: NPD | D3: Planned
A4: R1337.2 | B4: K8.0 Resi Concealed Sidewall ECLH | C4: NPD | D4: Planned
A5: R1430.1A | B5: K11.2 Low Profile In Rack Storage Sprinkler | C5: NPD | D5: Planned
A6: R1430.1B | B6: K8.0 Low Profile In Rack Storage Sprinkler | C6: NPD | D6: Planned
A7: R1430.1C | B7: K5.6 Low Profile In Rack Storage Sprinkler | C7: NPD | D7: Planned
A8: R1514.1 | B8: K4.9 Resi Concealed Pendent | C8: NPD | D8: Planned
A9: R1514.2 | B9: K3.0 Resi Concealed Pendent | C9: NPD | D9: Planned
A10: R1517 | B10: K22/K25 ESFR High Pressure | C10: NPD | D10: Planned
A11: R1517.1 | B11: K17 ESFR High Pressure | C11: NPD | D11: Planned
A12: R1518 | B12: Universal Cleanroom | C12: NPD | D12: Planned
... A34: T1528 | B34: V2603 Foam Nozzle | C34: Sprint | D34: Planned

Sheet Engineers
A1: Engineer | B1: CapacityOverrideHours
A2: Mike | B2: 0
A3: Karl | B3: 0
A4: Brian | B4: 0
A5: Hannah | B5: 0
A6: Marcelo | B6: 0
A7: Justin | B7: 0
A8: Aaron | B8: 0

Sheet Skills
A1: Engineer | B1: FEA | C1: CFD | D1: Deflector development | E1: VicFlex hose | F1: VicFlex bracket | G1: Vortex design | H1: Vortex operation | I1: Data acquisition | J1: Fire test protocols | K1: Failure / root cause analysis | L1: Statistical analysis | M1: Test fixture design | N1: Codes and standards | O1: Tolerance stackup
A2: Mike | B2: 0 | C2: 0 | D2: 0 | E2: 0 | F2: 0 | G2: 0 | H2: 0 | I2: 0 | J2: 0 | K2: 0 | L2: 0 | M2: 0 | N2: 0 | O2: 0
A3: Karl | B3: 0 | C3: 0 | D3: 0 | E3: 0 | F3: 0 | G3: 0 | H3: 0 | I3: 0 | J3: 0 | K3: 0 | L3: 0 | M3: 0 | N3: 0 | O3: 0
A4: Brian | B4: 0 | C4: 0 | D4: 0 | E4: 0 | F4: 0 | G4: 0 | H4: 0 | I4: 0 | J4: 0 | K4: 0 | L4: 0 | M4: 0 | N4: 0 | O4: 0
A5: Hannah | B5: 0 | C5: 0 | D5: 0 | E5: 0 | F5: 0 | G5: 0 | H5: 0 | I5: 0 | J5: 0 | K5: 0 | L5: 0 | M5: 0 | N5: 0 | O5: 0
A6: Marcelo | B6: 0 | C6: 0 | D6: 0 | E6: 0 | F6: 0 | G6: 0 | H6: 0 | I6: 0 | J6: 0 | K6: 0 | L6: 0 | M6: 0 | N6: 0 | O6: 0
A7: Justin | B7: 0 | C7: 0 | D7: 0 | E7: 0 | F7: 0 | G7: 0 | H7: 0 | I7: 0 | J7: 0 | K7: 0 | L7: 0 | M7: 0 | N7: 0 | O7: 0
A8: Aaron | B8: 0 | C8: 0 | D8: 0 | E8: 0 | F8: 0 | G8: 0 | H8: 0 | I8: 0 | J8: 0 | K8: 0 | L8: 0 | M8: 0 | N8: 0 | O8: 0

Sheet Milestones
A1: ProjectID | B1: DR1 | C1: DR2 | D1: DR3 | E1: Launch
A2: R1337.1
A3: R1337.3
A4: R1337.2
A5: R1430.1A
A6: R1430.1B
A7: R1430.1C
A8: R1514.1
A9: R1514.2
A10: R1517
A11: R1517.1
A12: R1518 | B12: 45692 | C12: 45820 | D12: 46094 | E12: 46296
A13: R1527

Sheet Planned_ProjectMonth
A1: Month | B1: ProjectID | C1: TotalPlannedHours
A2: 46023 | B2: R1337.1 | C2: 40
A3: 46023 | B3: R1337.3 | C3: 40
A4: 46023 | B4: R1337.2 | C4: 40
A5: 46023 | B5: R1430.1A | C5: 120
A6: 46023 | B6: R1430.1B | C6: 60
A7: 46023 | B7: R1430.1C | C7: 60
A8: 46023 | B8: R1514.1 | C8: 30
A9: 46023 | B9: R1514.2 | C9: 60
A10: 46023 | B10: R1517
A11: 46023 | B11: R1517.1 | C11: 120
A12: 46023 | B12: R1518 | C12: 60
A13: 46023 | B13: R1527 | C13: 120
A14: 46023 | B14: S0001 | C14: 10
A15: 46023 | B15: S0057 | C15: 30
A16: 46023 | B16: S0013 | C16: 15
A17: 46023 | B17: S0062 | C17: 60

Sheet Planned_Allocations
A1: Month | B1: ProjectID | C1: Engineer | D1: AllocationPct | E1: ProjectType | F1: PlannedHoursAllocated
A2: 46023 | B2: R1337.1 | C2: Marcelo | D2: 1 | E2: =IFERROR(VLOOKUP(B2,Projects!A:C,3,FALSE),"") -> NPD | F2: 10
A3: 46023 | B3: R1337.3 | C3: Marcelo | D3: 1 | E3: =IFERROR(VLOOKUP(B3,Projects!A:C,3,FALSE),"") -> NPD | F3: 10
A4: 46023 | B4: R1337.2 | C4: Marcelo | D4: 1 | E4: =IFERROR(VLOOKUP(B4,Projects!A:C,3,FALSE),"") -> NPD | F4: 10
A5: 46023 | B5: R1430.1A | C5: Mike | D5: 1 | E5: =IFERROR(VLOOKUP(B5,Projects!A:C,3,FALSE),"") -> NPD | F5: 120
A6: 46023 | B6: R1430.1B | C6: Marcelo | D6: 1 | E6: =IFERROR(VLOOKUP(B6,Projects!A:C,3,FALSE),"") -> NPD | F6: 120
A7: 46023 | B7: R1430.1C | C7: Justin | D7: 1 | E7: =IFERROR(VLOOKUP(B7,Projects!A:C,3,FALSE),"") -> NPD | F7: 120
A8: 46023 | B8: R1514.1 | C8: Mike | D8: 1 | E8: =IFERROR(VLOOKUP(B8,Projects!A:C,3,FALSE),"") -> NPD | F8: 10
A9: 46023 | B9: R1514.2 | C9: Justin | D9: 1 | E9: =IFERROR(VLOOKUP(B9,Projects!A:C,3,FALSE),"") -> NPD | F9: 10
A10: 46023 | B10: R1517 | E10: =IFERROR(VLOOKUP(B10,Projects!A:C,3,FALSE),"") -> NPD
A11: 46023 | B11: R1517.1 | C11: Hannah | D11: 1 | E11: =IFERROR(VLOOKUP(B11,Projects!A:C,3,FALSE),"") -> NPD | F11: 120
A12: 46023 | B12: R1518 | C12: Brian | D12: 1 | E12: =IFERROR(VLOOKUP(B12,Projects!A:C,3,FALSE),"") -> NPD | F12: 60
A13: 46023 | B13: R1527 | C13: Aaron | D13: 1 | E13: =IFERROR(VLOOKUP(B13,Projects!A:C,3,FALSE),"") -> NPD | F13: 60
A14: 46023 | B14: S0057 | C14: Brian | D14: 1 | E14: =IFERROR(VLOOKUP(B14,Projects!A:C,3,FALSE),"") -> Sustaining | F14: 10
A15: 46023 | B15: S0062 | C15: Aaron | D15: 1 | E15: =IFERROR(VLOOKUP(B15,Projects!A:C,3,FALSE),"") -> Sustaining | F15: 60
A16: 46023 | B16: T1528 | C16: Karl | D16: 1 | E16: =IFERROR(VLOOKUP(B16,Projects!A:C,3,FALSE),"") -> Sprint | F16: 10

Sheet Actual_Hours
A1: Month | B1: ProjectID | C1: Engineer | D1: WorkClass | E1: ProjectType | F1: ActualHours
A2: 46023 | B2: R1430.1A | C2: Mike | D2: =IFERROR(VLOOKUP(B2,Projects!A:D,4,FALSE),"") -> Planned | E2: =IFERROR(VLOOKUP(B2,Projects!A:C,3,FALSE),"") -> NPD | F2: 166
A3: 46023 | B3: R0999 | C3: Mike | D3: =IFERROR(VLOOKUP(B3,Projects!A:D,4,FALSE),"") -> Planned | E3: =IFERROR(VLOOKUP(B3,Projects!A:C,3,FALSE),"") -> Out of Office | F3: 8
A4: 46023 | B4: R0996 | C4: Mike | D4: =IFERROR(VLOOKUP(B4,Projects!A:D,4,FALSE),"") -> Planned | E4: =IFERROR(VLOOKUP(B4,Projects!A:C,3,FALSE),"") -> Admin | F4: 2
A5: 46023 | B5: R1518 | C5: Brian | D5: =IFERROR(VLOOKUP(B5,Projects!A:D,4,FALSE),"") -> Planned | E5: =IFERROR(VLOOKUP(B5,Projects!A:C,3,FALSE),"") -> NPD | F5: 42.75
A6: 46023 | B6: S0004 | C6: Brian | D6: =IFERROR(VLOOKUP(B6,Projects!A:D,4,FALSE),"") -> Planned | E6: =IFERROR(VLOOKUP(B6,Projects!A:C,3,FALSE),"") -> Sustaining | F6: 27
A7: 46023 | B7: R0992 | C7: Brian | D7: =IFERROR(VLOOKUP(B7,Projects!A:D,4,FALSE),"") -> Unplanned/Firefighting | E7: =IFERROR(VLOOKUP(B7,Projects!A:C,3,FALSE),"") -> Sustaining | F7: 19.75
A8: 46023 | B8: R0996 | C8: Brian | D8: =IFERROR(VLOOKUP(B8,Projects!A:D,4,FALSE),"") -> Planned | E8: =IFERROR(VLOOKUP(B8,Projects!A:C,3,FALSE),"") -> Admin | F8: 18.5
A9: 46023 | B9: R0999 | C9: Brian | D9: =IFERROR(VLOOKUP(B9,Projects!A:D,4,FALSE),"") -> Planned | E9: =IFERROR(VLOOKUP(B9,Projects!A:C,3,FALSE),"") -> Out of Office | F9: 16
A10: 46023 | B10: S0062 | C10: Brian | D10: =IFERROR(VLOOKUP(B10,Projects!A:D,4,FALSE),"") -> Planned | E10: =IFERROR(VLOOKUP(B10,Projects!A:C,3,FALSE),"") -> Sustaining | F10: 13.75
A11: 46023 | B11: S0002 | C11: Brian | D11: =IFERROR(VLOOKUP(B11,Projects!A:D,4,FALSE),"") -> Unplanned/Firefighting | E11: =IFERROR(VLOOKUP(B11,Projects!A:C,3,FALSE),"") -> Sustaining | F11: 8
A12: 46023 | B12: S0005 | C12: Brian | D12: =IFERROR(VLOOKUP(B12,Projects!A:D,4,FALSE),"") -> Unplanned/Firefighting | E12: =IFERROR(VLOOKUP(B12,Projects!A:C,3,FALSE),"") -> Sustaining | F12: 6.5
A13: 46023 | B13: R0991 | C13: Brian | D13: =IFERROR(VLOOKUP(B13,Projects!A:D,4,FALSE),"") -> Unplanned/Firefighting | E13: =IFERROR(VLOOKUP(B13,Projects!A:C,3,FALSE),"") -> Sustaining | F13: 6.5
... A47: 46023 | B47: R0996 | C47: Aaron | D47: =IFERROR(VLOOKUP(B47,Projects!A:D,4,FALSE),"") -> Planned | E47: =IFERROR(VLOOKUP(B47,Projects!A:C,3,FALSE),"") -> Admin | F47: 6.5
D48: =IFERROR(VLOOKUP(B48,Projects!A:D,4,FALSE),"") | E48: =IFERROR(VLOOKUP(B48,Projects!A:C,3,FALSE),"")

Sheet Lab_Tech_Hours
A1: Month | B1: Engineer | C1: LabTechHours
A2: 46023 | B2: Mike | C2: 1
A3: 46023 | B3: Karl | C3: 0
A4: 46023 | B4: Brian | C4: 26.25
A5: 46023 | B5: Hannah | C5: 28.5
A6: 46023 | B6: Marcelo | C6: 70.25
A7: 46023 | B7: Justin | C7: 70
A8: 46023 | B8: Aaron | C8: 0
A9: 46054 | B9: Mike | C9: 8
A10: 46054 | B10: Karl | C10: 0
A11: 46054 | B11: Brian | C11: 11.25
A12: 46054 | B12: Hannah | C12: 6
A13: 46054 | B13: Marcelo | C13: 11
... A15: 46054 | B15: Aaron | C15: 5

Sheet Params
A1: Parameter | B1: Value
A2: StdMonthlyCapacityHours | B2: 140
A3: SelectedMonth | B3: 46023
A4: SelectedProject | B4: R1518
A5: OverUtilizationThresholdPct | B5: 1

Sheet Calc
A1: Calculated summaries (do not edit)
A3: SelectedMonth | B3: =Params!B3 -> 46023 | D3: SelectedProject | E3: =Params!B4 -> R1518
A6: MonthLabel | B6: Planned_NPD | C6: Planned_Sustaining | D6: Planned_Sprint | E6: Actual_NPD | F6: Actual_Sustaining | G6: Actual_Sprint | H6: Actual_Firefighting | I6: LabTech_Total | J6: MonthDate
A7: 2026-01 | B7: =SUMIFS(tblPlannedAlloc[PlannedHoursAllocated],tblPlannedAlloc[Month],$J7,tblPlannedAlloc[ProjectType],"NPD") -> 650 | C7: =SUMIFS(tblPlannedAlloc[PlannedHoursAllocated],tblPlannedAlloc[Month],$J7,tblPlannedAlloc[ProjectType],"Sustaining") -> 70 | D7: =SUMIFS(tblPlannedAlloc[PlannedHoursAllocated],tblPlannedAlloc[Month],$J7,tblPlannedAlloc[ProjectType],"Sprint") -> 10 | E7: =SUMIFS(tblActualHours[ActualHours],tblActualHours[Month],$J7,tblActualHours[ProjectType],"NPD") -> 670 | F7: =SUMIFS(tblActualHours[ActualHours],tblActualHours[Month],$J7,tblActualHours[ProjectType],"Sustaining") -> 231.25 | G7: =SUMIFS(tblActualHours[ActualHours],tblActualHours[Month],$J7,tblActualHours[WorkClass],"Sprint") -> 0 | H7: =SUMIFS(tblActualHours[ActualHours],tblActualHours[Month],$J7,tblActualHours[WorkClass],"Unplanned/Firefighting") -> 101.5 | I7: =SUMIFS(tblLabTech[LabTechHours],tblLabTech[Month],$J7) -> 196 | J7: 46023
A8: 2026-02 | B8: =SUMIFS(tblPlannedAlloc[PlannedHoursAllocated],tblPlannedAlloc[Month],$J8,tblPlannedAlloc[ProjectType],"NPD") -> 0 | C8: =SUMIFS(tblPlannedAlloc[PlannedHoursAllocated],tblPlannedAlloc[Month],$J8,tblPlannedAlloc[ProjectType],"Sustaining") -> 0 | D8: =SUMIFS(tblPlannedAlloc[PlannedHoursAllocated],tblPlannedAlloc[Month],$J8,tblPlannedAlloc[ProjectType],"Sprint") -> 0 | E8: =SUMIFS(tblActualHours[ActualHours],tblActualHours[Month],$J8,tblActualHours[ProjectType],"NPD") -> 0 | F8: =SUMIFS(tblActualHours[ActualHours],tblActualHours[Month],$J8,tblActualHours[ProjectType],"Sustaining") -> 0 | G8: =SUMIFS(tblActualHours[ActualHours],tblActualHours[Month],$J8,tblActualHours[WorkClass],"Sprint") -> 0 | H8: =SUMIFS(tblActualHours[ActualHours],tblActualHours[Month],$J8,tblActualHours[WorkClass],"Unplanned/Firefighting") -> 0 | I8: =SUMIFS(tblLabTech[LabTechHours],tblLabTech[Month],$J8) -> 57.25 | J8: 46054
A9: 2026-03 | B9: =SUMIFS(tblPlannedAlloc[PlannedHoursAllocated],tblPlannedAlloc[Month],$J9,tblPlannedAlloc[ProjectType],"NPD") -> 0 | C9: =SUMIFS(tblPlannedAlloc[PlannedHoursAllocated],tblPlannedAlloc[Month],$J9,tblPlannedAlloc[ProjectType],"Sustaining") -> 0 | D9: =SUMIFS(tblPlannedAlloc[PlannedHoursAllocated],tblPlannedAlloc[Month],$J9,tblPlannedAlloc[ProjectType],"Sprint") -> 0 | E9: =SUMIFS(tblActualHours[ActualHours],tblActualHours[Month],$J9,tblActualHours[ProjectType],"NPD") -> 0 | F9: =SUMIFS(tblActualHours[ActualHours],tblActualHours[Month],$J9,tblActualHours[ProjectType],"Sustaining") -> 0 | G9: =SUMIFS(tblActualHours[ActualHours],tblActualHours[Month],$J9,tblActualHours[WorkClass],"Sprint") -> 0 | H9: =SUMIFS(tblActualHours[ActualHours],tblActualHours[Month],$J9,tblActualHours[WorkClass],"Unplanned/Firefighting") -> 0 | I9: =SUMIFS(tblLabTech[LabTechHours],tblLabTech[Month],$J9) -> 0 | J9: 46082
A10: 2026-04 | B10: =SUMIFS(tblPlannedAlloc[PlannedHoursAllocated],tblPlannedAlloc[Month],$J10,tblPlannedAlloc[ProjectType],"NPD") -> 0 | C10: =SUMIFS(tblPlannedAlloc[PlannedHoursAllocated],tblPlannedAlloc[Month],$J10,tblPlannedAlloc[ProjectType],"Sustaining") -> 0 | D10: =SUMIFS(tblPlannedAlloc[PlannedHoursAllocated],tblPlannedAlloc[Month],$J10,tblPlannedAlloc[ProjectType],"Sprint") -> 0 | E10: =SUMIFS(tblActualHours[ActualHours],tblActualHours[Month],$J10,tblActualHours[ProjectType],"NPD") -> 0 | F10: =SUMIFS(tblActualHours[ActualHours],tblActualHours[Month],$J10,tblActualHours[ProjectType],"Sustaining") -> 0 | G10: =SUMIFS(tblActualHours[ActualHours],tblActualHours[Month],$J10,tblActualHours[WorkClass],"Sprint") -> 0 | H10: =SUMIFS(tblActualHours[ActualHours],tblActualHours[Month],$J10,tblActualHours[WorkClass],"Unplanned/Firefighting") -> 0 | I10: =SUMIFS(tblLabTech[LabTechHours],tblLabTech[Month],$J10) -> 0 | J10: 46113
A11: 2026-05 | B11: =SUMIFS(tblPlannedAlloc[PlannedHoursAllocated],tblPlannedAlloc[Month],$J11,tblPlannedAlloc[ProjectType],"NPD") -> 0 | C11: =SUMIFS(tblPlannedAlloc[PlannedHoursAllocated],tblPlannedAlloc[Month],$J11,tblPlannedAlloc[ProjectType],"Sustaining") -> 0 | D11: =SUMIFS(tblPlannedAlloc[PlannedHoursAllocated],tblPlannedAlloc[Month],$J11,tblPlannedAlloc[ProjectType],"Sprint") -> 0 | E11: =SUMIFS(tblActualHours[ActualHours],tblActualHours[Month],$J11,tblActualHours[ProjectType],"NPD") -> 0 | F11: =SUMIFS(tblActualHours[ActualHours],tblActualHours[Month],$J11,tblActualHours[ProjectType],"Sustaining") -> 0 | G11: =SUMIFS(tblActualHours[ActualHours],tblActualHours[Month],$J11,tblActualHours[WorkClass],"Sprint") -> 0 | H11: =SUMIFS(tblActualHours[ActualHours],tblActualHours[Month],$J11,tblActualHours[WorkClass],"Unplanned/Firefighting") -> 0 | I11: =SUMIFS(tblLabTech[LabTechHours],tblLabTech[Month],$J11) -> 0 | J11: 46143
A12: 2026-06 | B12: =SUMIFS(tblPlannedAlloc[PlannedHoursAllocated],tblPlannedAlloc[Month],$J12,tblPlannedAlloc[ProjectType],"NPD") -> 0 | C12: =SUMIFS(tblPlannedAlloc[PlannedHoursAllocated],tblPlannedAlloc[Month],$J12,tblPlannedAlloc[ProjectType],"Sustaining") -> 0 | D12: =SUMIFS(tblPlannedAlloc[PlannedHoursAllocated],tblPlannedAlloc[Month],$J12,tblPlannedAlloc[ProjectType],"Sprint") -> 0 | E12: =SUMIFS(tblActualHours[ActualHours],tblActualHours[Month],$J12,tblActualHours[ProjectType],"NPD") -> 0 | F12: =SUMIFS(tblActualHours[ActualHours],tblActualHours[Month],$J12,tblActualHours[ProjectType],"Sustaining") -> 0 | G12: =SUMIFS(tblActualHours[ActualHours],tblActualHours[Month],$J12,tblActualHours[WorkClass],"Sprint") -> 0 | H12: =SUMIFS(tblActualHours[ActualHours],tblActualHours[Month],$J12,tblActualHours[WorkClass],"Unplanned/Firefighting") -> 0 | I12: =SUMIFS(tblLabTech[LabTechHours],tblLabTech[Month],$J12) -> 0 | J12: 46174
A13: 2026-07 | B13: =SUMIFS(tblPlannedAlloc[PlannedHoursAllocated],tblPlannedAlloc[Month],$J13,tblPlannedAlloc[ProjectType],"NPD") -> 0 | C13: =SUMIFS(tblPlannedAlloc[PlannedHoursAllocated],tblPlannedAlloc[Month],$J13,tblPlannedAlloc[ProjectType],"Sustaining") -> 0 | D13: =SUMIFS(tblPlannedAlloc[PlannedHoursAllocated],tblPlannedAlloc[Month],$J13,tblPlannedAlloc[ProjectType],"Sprint") -> 0 | E13: =SUMIFS(tblActualHours[ActualHours],tblActualHours[Month],$J13,tblActualHours[ProjectType],"NPD") -> 0 | F13: =SUMIFS(tblActualHours[ActualHours],tblActualHours[Month],$J13,tblActualHours[ProjectType],"Sustaining") -> 0 | G13: =SUMIFS(tblActualHours[ActualHours],tblActualHours[Month],$J13,tblActualHours[WorkClass],"Sprint") -> 0 | H13: =SUMIFS(tblActualHours[ActualHours],tblActualHours[Month],$J13,tblActualHours[WorkClass],"Unplanned/Firefighting") -> 0 | I13: =SUMIFS(tblLabTech[LabTechHours],tblLabTech[Month],$J13) -> 0 | J13: 46204
A14: 2026-08 | B14: =SUMIFS(tblPlannedAlloc[PlannedHoursAllocated],tblPlannedAlloc[Month],$J14,tblPlannedAlloc[ProjectType],"NPD") -> 0 | C14: =SUMIFS(tblPlannedAlloc[PlannedHoursAllocated],tblPlannedAlloc[Month],$J14,tblPlannedAlloc[ProjectType],"Sustaining") -> 0 | D14: =SUMIFS(tblPlannedAlloc[PlannedHoursAllocated],tblPlannedAlloc[Month],$J14,tblPlannedAlloc[ProjectType],"Sprint") -> 0 | E14: =SUMIFS(tblActualHours[ActualHours],tblActualHours[Month],$J14,tblActualHours[ProjectType],"NPD") -> 0 | F14: =SUMIFS(tblActualHours[ActualHours],tblActualHours[Month],$J14,tblActualHours[ProjectType],"Sustaining") -> 0 | G14: =SUMIFS(tblActualHours[ActualHours],tblActualHours[Month],$J14,tblActualHours[WorkClass],"Sprint") -> 0 | H14: =SUMIFS(tblActualHours[ActualHours],tblActualHours[Month],$J14,tblActualHours[WorkClass],"Unplanned/Firefighting") -> 0 | I14: =SUMIFS(tblLabTech[LabTechHours],tblLabTech[Month],$J14) -> 0 | J14: 46235
A15: 2026-09 | B15: =SUMIFS(tblPlannedAlloc[PlannedHoursAllocated],tblPlannedAlloc[Month],$J15,tblPlannedAlloc[ProjectType],"NPD") -> 0 | C15: =SUMIFS(tblPlannedAlloc[PlannedHoursAllocated],tblPlannedAlloc[Month],$J15,tblPlannedAlloc[ProjectType],"Sustaining") -> 0 | D15: =SUMIFS(tblPlannedAlloc[PlannedHoursAllocated],tblPlannedAlloc[Month],$J15,tblPlannedAlloc[ProjectType],"Sprint") -> 0 | E15: =SUMIFS(tblActualHours[ActualHours],tblActualHours[Month],$J15,tblActualHours[ProjectType],"NPD") -> 0 | F15: =SUMIFS(tblActualHours[ActualHours],tblActualHours[Month],$J15,tblActualHours[ProjectType],"Sustaining") -> 0 | G15: =SUMIFS(tblActualHours[ActualHours],tblActualHours[Month],$J15,tblActualHours[WorkClass],"Sprint") -> 0 | H15: =SUMIFS(tblActualHours[ActualHours],tblActualHours[Month],$J15,tblActualHours[WorkClass],"Unplanned/Firefighting") -> 0 | I15: =SUMIFS(tblLabTech[LabTechHours],tblLabTech[Month],$J15) -> 0 | J15: 46266
A16: 2026-10 | B16: =SUMIFS(tblPlannedAlloc[PlannedHoursAllocated],tblPlannedAlloc[Month],$J16,tblPlannedAlloc[ProjectType],"NPD") -> 0 | C16: =SUMIFS(tblPlannedAlloc[PlannedHoursAllocated],tblPlannedAlloc[Month],$J16,tblPlannedAlloc[ProjectType],"Sustaining") -> 0 | D16: =SUMIFS(tblPlannedAlloc[PlannedHoursAllocated],tblPlannedAlloc[Month],$J16,tblPlannedAlloc[ProjectType],"Sprint") -> 0 | E16: =SUMIFS(tblActualHours[ActualHours],tblActualHours[Month],$J16,tblActualHours[ProjectType],"NPD") -> 0 | F16: =SUMIFS(tblActualHours[ActualHours],tblActualHours[Month],$J16,tblActualHours[ProjectType],"Sustaining") -> 0 | G16: =SUMIFS(tblActualHours[ActualHours],tblActualHours[Month],$J16,tblActualHours[WorkClass],"Sprint") -> 0 | H16: =SUMIFS(tblActualHours[ActualHours],tblActualHours[Month],$J16,tblActualHours[WorkClass],"Unplanned/Firefighting") -> 0 | I16: =SUMIFS(tblLabTech[LabTechHours],tblLabTech[Month],$J16) -> 0 | J16: 46296
A17: 2026-11 | B17: =SUMIFS(tblPlannedAlloc[PlannedHoursAllocated],tblPlannedAlloc[Month],$J17,tblPlannedAlloc[ProjectType],"NPD") -> 0 | C17: =SUMIFS(tblPlannedAlloc[PlannedHoursAllocated],tblPlannedAlloc[Month],$J17,tblPlannedAlloc[ProjectType],"Sustaining") -> 0 | D17: =SUMIFS(tblPlannedAlloc[PlannedHoursAllocated],tblPlannedAlloc[Month],$J17,tblPlannedAlloc[ProjectType],"Sprint") -> 0 | E17: =SUMIFS(tblActualHours[ActualHours],tblActualHours[Month],$J17,tblActualHours[ProjectType],"NPD") -> 0 | F17: =SUMIFS(tblActualHours[ActualHours],tblActualHours[Month],$J17,tblActualHours[ProjectType],"Sustaining") -> 0 | G17: =SUMIFS(tblActualHours[ActualHours],tblActualHours[Month],$J17,tblActualHours[WorkClass],"Sprint") -> 0 | H17: =SUMIFS(tblActualHours[ActualHours],tblActualHours[Month],$J17,tblActualHours[WorkClass],"Unplanned/Firefighting") -> 0 | I17: =SUMIFS(tblLabTech[LabTechHours],tblLabTech[Month],$J17) -> 0 | J17: 46327
A18: 2026-12 | B18: =SUMIFS(tblPlannedAlloc[PlannedHoursAllocated],tblPlannedAlloc[Month],$J18,tblPlannedAlloc[ProjectType],"NPD") -> 0 | C18: =SUMIFS(tblPlannedAlloc[PlannedHoursAllocated],tblPlannedAlloc[Month],$J18,tblPlannedAlloc[ProjectType],"Sustaining") -> 0 | D18: =SUMIFS(tblPlannedAlloc[PlannedHoursAllocated],tblPlannedAlloc[Month],$J18,tblPlannedAlloc[ProjectType],"Sprint") -> 0 | E18: =SUMIFS(tblActualHours[ActualHours],tblActualHours[Month],$J18,tblActualHours[ProjectType],"NPD") -> 0 | F18: =SUMIFS(tblActualHours[ActualHours],tblActualHours[Month],$J18,tblActualHours[ProjectType],"Sustaining") -> 0 | G18: =SUMIFS(tblActualHours[ActualHours],tblActualHours[Month],$J18,tblActualHours[WorkClass],"Sprint") -> 0 | H18: =SUMIFS(tblActualHours[ActualHours],tblActualHours[Month],$J18,tblActualHours[WorkClass],"Unplanned/Firefighting") -> 0 | I18: =SUMIFS(tblLabTech[LabTechHours],tblLabTech[Month],$J18) -> 0 | J18: 46357
A22: MonthLabel | B22: Planned_SelectedProject | C22: Actual_SelectedProject | D22: MonthDate
A23: 2026-01 | B23: =SUMIFS(tblPlannedAlloc[PlannedHoursAllocated],tblPlannedAlloc[Month],$D23,tblPlannedAlloc[ProjectID],$E$3) -> 60 | C23: =SUMIFS(tblActualHours[ActualHours],tblActualHours[Month],$D23,tblActualHours[ProjectID],$E$3) -> 42.75 | D23: 46023
A24: 2026-02 | B24: =SUMIFS(tblPlannedAlloc[PlannedHoursAllocated],tblPlannedAlloc[Month],$D24,tblPlannedAlloc[ProjectID],$E$3) -> 0 | C24: =SUMIFS(tblActualHours[ActualHours],tblActualHours[Month],$D24,tblActualHours[ProjectID],$E$3) -> 0 | D24: 46054
A25: 2026-03 | B25: =SUMIFS(tblPlannedAlloc[PlannedHoursAllocated],tblPlannedAlloc[Month],$D25,tblPlannedAlloc[ProjectID],$E$3) -> 0 | C25: =SUMIFS(tblActualHours[ActualHours],tblActualHours[Month],$D25,tblActualHours[ProjectID],$E$3) -> 0 | D25: 46082
A26: 2026-04 | B26: =SUMIFS(tblPlannedAlloc[PlannedHoursAllocated],tblPlannedAlloc[Month],$D26,tblPlannedAlloc[ProjectID],$E$3) -> 0 | C26: =SUMIFS(tblActualHours[ActualHours],tblActualHours[Month],$D26,tblActualHours[ProjectID],$E$3) -> 0 | D26: 46113
A27: 2026-05 | B27: =SUMIFS(tblPlannedAlloc[PlannedHoursAllocated],tblPlannedAlloc[Month],$D27,tblPlannedAlloc[ProjectID],$E$3) -> 0 | C27: =SUMIFS(tblActualHours[ActualHours],tblActualHours[Month],$D27,tblActualHours[ProjectID],$E$3) -> 0 | D27: 46143
A28: 2026-06 | B28: =SUMIFS(tblPlannedAlloc[PlannedHoursAllocated],tblPlannedAlloc[Month],$D28,tblPlannedAlloc[ProjectID],$E$3) -> 0 | C28: =SUMIFS(tblActualHours[ActualHours],tblActualHours[Month],$D28,tblActualHours[ProjectID],$E$3) -> 0 | D28: 46174
A29: 2026-07 | B29: =SUMIFS(tblPlannedAlloc[PlannedHoursAllocated],tblPlannedAlloc[Month],$D29,tblPlannedAlloc[ProjectID],$E$3) -> 0 | C29: =SUMIFS(tblActualHours[ActualHours],tblActualHours[Month],$D29,tblActualHours[ProjectID],$E$3) -> 0 | D29: 46204
A30: 2026-08 | B30: =SUMIFS(tblPlannedAlloc[PlannedHoursAllocated],tblPlannedAlloc[Month],$D30,tblPlannedAlloc[ProjectID],$E$3) -> 0 | C30: =SUMIFS(tblActualHours[ActualHours],tblActualHours[Month],$D30,tblActualHours[ProjectID],$E$3) -> 0 | D30: 46235
A31: 2026-09 | B31: =SUMIFS(tblPlannedAlloc[PlannedHoursAllocated],tblPlannedAlloc[Month],$D31,tblPlannedAlloc[ProjectID],$E$3) -> 0 | C31: =SUMIFS(tblActualHours[ActualHours],tblActualHours[Month],$D31,tblActualHours[ProjectID],$E$3) -> 0 | D31: 46266
A32: 2026-10 | B32: =SUMIFS(tblPlannedAlloc[PlannedHoursAllocated],tblPlannedAlloc[Month],$D32,tblPlannedAlloc[ProjectID],$E$3) -> 0 | C32: =SUMIFS(tblActualHours[ActualHours],tblActualHours[Month],$D32,tblActualHours[ProjectID],$E$3) -> 0 | D32: 46296
A33: 2026-11 | B33: =SUMIFS(tblPlannedAlloc[PlannedHoursAllocated],tblPlannedAlloc[Month],$D33,tblPlannedAlloc[ProjectID],$E$3) -> 0 | C33: =SUMIFS(tblActualHours[ActualHours],tblActualHours[Month],$D33,tblActualHours[ProjectID],$E$3) -> 0 | D33: 46327
A34: 2026-12 | B34: =SUMIFS(tblPlannedAlloc[PlannedHoursAllocated],tblPlannedAlloc[Month],$D34,tblPlannedAlloc[ProjectID],$E$3) -> 0 | C34: =SUMIFS(tblActualHours[ActualHours],tblActualHours[Month],$D34,tblActualHours[ProjectID],$E$3) -> 0 | D34: 46357
A38: ProjectIndex | B38: EngineerIndex | C38: PlannedHours
A39: 1 | B39: 1 | C39: =SUMIFS(tblPlannedAlloc[PlannedHoursAllocated],tblPlannedAlloc[Month],$B$3,tblPlannedAlloc[ProjectID],"R1337.1",tblPlannedAlloc[Engineer],"Mike") -> 0
A40: 1 | B40: 2 | C40: =SUMIFS(tblPlannedAlloc[PlannedHoursAllocated],tblPlannedAlloc[Month],$B$3,tblPlannedAlloc[ProjectID],"R1337.1",tblPlannedAlloc[Engineer],"Karl") -> 0
A41: 1 | B41: 3 | C41: =SUMIFS(tblPlannedAlloc[PlannedHoursAllocated],tblPlannedAlloc[Month],$B$3,tblPlannedAlloc[ProjectID],"R1337.1",tblPlannedAlloc[Engineer],"Brian") -> 0
A42: 1 | B42: 4 | C42: =SUMIFS(tblPlannedAlloc[PlannedHoursAllocated],tblPlannedAlloc[Month],$B$3,tblPlannedAlloc[ProjectID],"R1337.1",tblPlannedAlloc[Engineer],"Hannah") -> 0
A43: 1 | B43: 5 | C43: =SUMIFS(tblPlannedAlloc[PlannedHoursAllocated],tblPlannedAlloc[Month],$B$3,tblPlannedAlloc[ProjectID],"R1337.1",tblPlannedAlloc[Engineer],"Marcelo") -> 10
A44: 1 | B44: 6 | C44: =SUMIFS(tblPlannedAlloc[PlannedHoursAllocated],tblPlannedAlloc[Month],$B$3,tblPlannedAlloc[ProjectID],"R1337.1",tblPlannedAlloc[Engineer],"Justin") -> 0
A45: 1 | B45: 7 | C45: =SUMIFS(tblPlannedAlloc[PlannedHoursAllocated],tblPlannedAlloc[Month],$B$3,tblPlannedAlloc[ProjectID],"R1337.1",tblPlannedAlloc[Engineer],"Aaron") -> 0
A46: 2 | B46: 1 | C46: =SUMIFS(tblPlannedAlloc[PlannedHoursAllocated],tblPlannedAlloc[Month],$B$3,tblPlannedAlloc[ProjectID],"R1337.3",tblPlannedAlloc[Engineer],"Mike") -> 0
A47: 2 | B47: 2 | C47: =SUMIFS(tblPlannedAlloc[PlannedHoursAllocated],tblPlannedAlloc[Month],$B$3,tblPlannedAlloc[ProjectID],"R1337.3",tblPlannedAlloc[Engineer],"Karl") -> 0
A48: 2 | B48: 3 | C48: =SUMIFS(tblPlannedAlloc[PlannedHoursAllocated],tblPlannedAlloc[Month],$B$3,tblPlannedAlloc[ProjectID],"R1337.3",tblPlannedAlloc[Engineer],"Brian") -> 0
A49: 2 | B49: 4 | C49: =SUMIFS(tblPlannedAlloc[PlannedHoursAllocated],tblPlannedAlloc[Month],$B$3,tblPlannedAlloc[ProjectID],"R1337.3",tblPlannedAlloc[Engineer],"Hannah") -> 0
...

Sheet Dashboard
A1: Team Resource & Planning Dashboard
A2: Set SelectedMonth and SelectedProject in Params. Paste LP actuals into Actual_Hours. Fill planned hours + allocations to drive the resource view.
A4: Skill Heat Map (0–5)
A5: Engineer | B5: FEA | C5: CFD | D5: Deflector development | E5: VicFlex hose | F5: VicFlex bracket | G5: Vortex design | H5: Vortex operation | I5: Data acquisition | J5: Fire test protocols | K5: Failure / root cause analysis | L5: Statistical analysis | M5: Test fixture design | N5: Codes and standards | O5: Tolerance stackup
A6: =Skills!A2 -> Mike | B6: =Skills!B2 -> 0 | C6: =Skills!C2 -> 0 | D6: =Skills!D2 -> 0 | E6: =Skills!E2 -> 0 | F6: =Skills!F2 -> 0 | G6: =Skills!G2 -> 0 | H6: =Skills!H2 -> 0 | ... O6: =Skills!O2 -> 0
A7: =Skills!A3 -> Karl | B7: =Skills!B3 -> 0 | C7: =Skills!C3 -> 0 | D7: =Skills!D3 -> 0 | E7: =Skills!E3 -> 0 | F7: =Skills!F3 -> 0 | G7: =Skills!G3 -> 0 | H7: =Skills!H3 -> 0 | ... O7: =Skills!O3 -> 0
A8: =Skills!A4 -> Brian | B8: =Skills!B4 -> 0 | C8: =Skills!C4 -> 0 | D8: =Skills!D4 -> 0 | E8: =Skills!E4 -> 0 | F8: =Skills!F4 -> 0 | G8: =Skills!G4 -> 0 | H8: =Skills!H4 -> 0 | ... O8: =Skills!O4 -> 0
A9: =Skills!A5 -> Hannah | B9: =Skills!B5 -> 0 | C9: =Skills!C5 -> 0 | D9: =Skills!D5 -> 0 | E9: =Skills!E5 -> 0 | F9: =Skills!F5 -> 0 | G9: =Skills!G5 -> 0 | H9: =Skills!H5 -> 0 | ... O9: =Skills!O5 -> 0
A10: =Skills!A6 -> Marcelo | B10: =Skills!B6 -> 0 | C10: =Skills!C6 -> 0 | D10: =Skills!D6 -> 0 | E10: =Skills!E6 -> 0 | F10: =Skills!F6 -> 0 | G10: =Skills!G6 -> 0 | H10: =Skills!H6 -> 0 | ... O10: =Skills!O6 -> 0
A11: =Skills!A7 -> Justin | B11: =Skills!B7 -> 0 | C11: =Skills!C7 -> 0 | D11: =Skills!D7 -> 0 | E11: =Skills!E7 -> 0 | F11: =Skills!F7 -> 0 | G11: =Skills!G7 -> 0 | H11: =Skills!H7 -> 0 | ... O11: =Skills!O7 -> 0
A12: =Skills!A8 -> Aaron | B12: =Skills!B8 -> 0 | C12: =Skills!C8 -> 0 | D12: =Skills!D8 -> 0 | E12: =Skills!E8 -> 0 | F12: =Skills!F8 -> 0 | G12: =Skills!G8 -> 0 | H12: =Skills!H8 -> 0 | ... O12: =Skills!O8 -> 0
A13: Planned Utilization Heat Map (Engineer x Month)
A15: Engineer | B15: 2026-01 | C15: 2026-02 | D15: 2026-03 | E15: 2026-04 | F15: 2026-05 | G15: 2026-06 | H15: 2026-07 | I15: 2026-08 | J15: 2026-09 | K15: 2026-10 | L15: 2026-11 | M15: 2026-12
A16: Mike | B16: =IFERROR(SUMIFS(tblPlannedAlloc[PlannedHoursAllocated],tblPlannedAlloc[Engineer],$A16,tblPlannedAlloc[Month],Months!$A$2)/Params!$B$2,0) -> 0.92857143 | C16: =IFERROR(SUMIFS(tblPlannedAlloc[PlannedHoursAllocated],tblPlannedAlloc[Engineer],$A16,tblPlannedAlloc[Month],Months!$A$3)/Params!$B$2,0) -> 0 | D16: =IFERROR(SUMIFS(tblPlannedAlloc[PlannedHoursAllocated],tblPlannedAlloc[Engineer],$A16,tblPlannedAlloc[Month],Months!$A$4)/Params!$B$2,0) -> 0 | E16: =IFERROR(SUMIFS(tblPlannedAlloc[PlannedHoursAllocated],tblPlannedAlloc[Engineer],$A16,tblPlannedAlloc[Month],Months!$A$5)/Params!$B$2,0) -> 0 | F16: =IFERROR(SUMIFS(tblPlannedAlloc[PlannedHoursAllocated],tblPlannedAlloc[Engineer],$A16,tblPlannedAlloc[Month],Months!$A$6)/Params!$B$2,0) -> 0 | G16: =IFERROR(SUMIFS(tblPlannedAlloc[PlannedHoursAllocated],tblPlannedAlloc[Engineer],$A16,tblPlannedAlloc[Month],Months!$A$7)/Params!$B$2,0) -> 0 | H16: =IFERROR(SUMIFS(tblPlannedAlloc[PlannedHoursAllocated],tblPlannedAlloc[Engineer],$A16,tblPlannedAlloc[Month],Months!$A$8)/Params!$B$2,0) -> 0 | I16: =IFERROR(SUMIFS(tblPlannedAlloc[PlannedHoursAllocated],tblPlannedAlloc[Engineer],$A16,tblPlannedAlloc[Month],Months!$A$9)/Params!$B$2,0) -> 0 | J16: =IFERROR(SUMIFS(tblPlannedAlloc[PlannedHoursAllocated],tblPlannedAlloc[Engineer],$A16,tblPlannedAlloc[Month],Months!$A$10)/Params!$B$2,0) -> 0 | K16: =IFERROR(SUMIFS(tblPlannedAlloc[PlannedHoursAllocated],tblPlannedAlloc[Engineer],$A16,tblPlannedAlloc[Month],Months!$A$11)/Params!$B$2,0) -> 0 | L16: =IFERROR(SUMIFS(tblPlannedAlloc[PlannedHoursAllocated],tblPlannedAlloc[Engineer],$A16,tblPlannedAlloc[Month],Months!$A$12)/Params!$B$2,0) -> 0 | M16: =IFERROR(SUMIFS(tblPlannedAlloc[PlannedHoursAllocated],tblPlannedAlloc[Engineer],$A16,tblPlannedAlloc[Month],Months!$A$13)/Params!$B$2,0) -> 0
A17: Karl | B17: =IFERROR(SUMIFS(tblPlannedAlloc[PlannedHoursAllocated],tblPlannedAlloc[Engineer],$A17,tblPlannedAlloc[Month],Months!$A$2)/Params!$B$2,0) -> 0.071428571 | C17: =IFERROR(SUMIFS(tblPlannedAlloc[PlannedHoursAllocated],tblPlannedAlloc[Engineer],$A17,tblPlannedAlloc[Month],Months!$A$3)/Params!$B$2,0) -> 0 | D17: =IFERROR(SUMIFS(tblPlannedAlloc[PlannedHoursAllocated],tblPlannedAlloc[Engineer],$A17,tblPlannedAlloc[Month],Months!$A$4)/Params!$B$2,0) -> 0 | E17: =IFERROR(SUMIFS(tblPlannedAlloc[PlannedHoursAllocated],tblPlannedAlloc[Engineer],$A17,tblPlannedAlloc[Month],Months!$A$5)/Params!$B$2,0) -> 0 | F17: =IFERROR(SUMIFS(tblPlannedAlloc[PlannedHoursAllocated],tblPlannedAlloc[Engineer],$A17,tblPlannedAlloc[Month],Months!$A$6)/Params!$B$2,0) -> 0 | G17: =IFERROR(SUMIFS(tblPlannedAlloc[PlannedHoursAllocated],tblPlannedAlloc[Engineer],$A17,tblPlannedAlloc[Month],Months!$A$7)/Params!$B$2,0) -> 0 | H17: =IFERROR(SUMIFS(tblPlannedAlloc[PlannedHoursAllocated],tblPlannedAlloc[Engineer],$A17,tblPlannedAlloc[Month],Months!$A$8)/Params!$B$2,0) -> 0 | I17: =IFERROR(SUMIFS(tblPlannedAlloc[PlannedHoursAllocated],tblPlannedAlloc[Engineer],$A17,tblPlannedAlloc[Month],Months!$A$9)/Params!$B$2,0) -> 0 | J17: =IFERROR(SUMIFS(tblPlannedAlloc[PlannedHoursAllocated],tblPlannedAlloc[Engineer],$A17,tblPlannedAlloc[Month],Months!$A$10)/Params!$B$2,0) -> 0 | K17: =IFERROR(SUMIFS(tblPlannedAlloc[PlannedHoursAllocated],tblPlannedAlloc[Engineer],$A17,tblPlannedAlloc[Month],Months!$A$11)/Params!$B$2,0) -> 0 | L17: =IFERROR(SUMIFS(tblPlannedAlloc[PlannedHoursAllocated],tblPlannedAlloc[Engineer],$A17,tblPlannedAlloc[Month],Months!$A$12)/Params!$B$2,0) -> 0 | M17: =IFERROR(SUMIFS(tblPlannedAlloc[PlannedHoursAllocated],tblPlannedAlloc[Engineer],$A17,tblPlannedAlloc[Month],Months!$A$13)/Params!$B$2,0) -> 0
A18: Brian | B18: =IFERROR(SUMIFS(tblPlannedAlloc[PlannedHoursAllocated],tblPlannedAlloc[Engineer],$A18,tblPlannedAlloc[Month],Months!$A$2)/Params!$B$2,0) -> 0.5 | C18: =IFERROR(SUMIFS(tblPlannedAlloc[PlannedHoursAllocated],tblPlannedAlloc[Engineer],$A18,tblPlannedAlloc[Month],Months!$A$3)/Params!$B$2,0) -> 0 | D18: =IFERROR(SUMIFS(tblPlannedAlloc[PlannedHoursAllocated],tblPlannedAlloc[Engineer],$A18,tblPlannedAlloc[Month],Months!$A$4)/Params!$B$2,0) -> 0 | E18: =IFERROR(SUMIFS(tblPlannedAlloc[PlannedHoursAllocated],tblPlannedAlloc[Engineer],$A18,tblPlannedAlloc[Month],Months!$A$5)/Params!$B$2,0) -> 0 | F18: =IFERROR(SUMIFS(tblPlannedAlloc[PlannedHoursAllocated],tblPlannedAlloc[Engineer],$A18,tblPlannedAlloc[Month],Months!$A$6)/Params!$B$2,0) -> 0 | G18: =IFERROR(SUMIFS(tblPlannedAlloc[PlannedHoursAllocated],tblPlannedAlloc[Engineer],$A18,tblPlannedAlloc[Month],Months!$A$7)/Params!$B$2,0) -> 0 | H18: =IFERROR(SUMIFS(tblPlannedAlloc[PlannedHoursAllocated],tblPlannedAlloc[Engineer],$A18,tblPlannedAlloc[Month],Months!$A$8)/Params!$B$2,0) -> 0 | I18: =IFERROR(SUMIFS(tblPlannedAlloc[PlannedHoursAllocated],tblPlannedAlloc[Engineer],$A18,tblPlannedAlloc[Month],Months!$A$9)/Params!$B$2,0) -> 0 | J18: =IFERROR(SUMIFS(tblPlannedAlloc[PlannedHoursAllocated],tblPlannedAlloc[Engineer],$A18,tblPlannedAlloc[Month],Months!$A$10)/Params!$B$2,0) -> 0 | K18: =IFERROR(SUMIFS(tblPlannedAlloc[PlannedHoursAllocated],tblPlannedAlloc[Engineer],$A18,tblPlannedAlloc[Month],Months!$A$11)/Params!$B$2,0) -> 0 | L18: =IFERROR(SUMIFS(tblPlannedAlloc[PlannedHoursAllocated],tblPlannedAlloc[Engineer],$A18,tblPlannedAlloc[Month],Months!$A$12)/Params!$B$2,0) -> 0 | M18: =IFERROR(SUMIFS(tblPlannedAlloc[PlannedHoursAllocated],tblPlannedAlloc[Engineer],$A18,tblPlannedAlloc[Month],Months!$A$13)/Params!$B$2,0) -> 0
A19: Hannah | B19: =IFERROR(SUMIFS(tblPlannedAlloc[PlannedHoursAllocated],tblPlannedAlloc[Engineer],$A19,tblPlannedAlloc[Month],Months!$A$2)/Params!$B$2,0) -> 0.85714286 | C19: =IFERROR(SUMIFS(tblPlannedAlloc[PlannedHoursAllocated],tblPlannedAlloc[Engineer],$A19,tblPlannedAlloc[Month],Months!$A$3)/Params!$B$2,0) -> 0 | D19: =IFERROR(SUMIFS(tblPlannedAlloc[PlannedHoursAllocated],tblPlannedAlloc[Engineer],$A19,tblPlannedAlloc[Month],Months!$A$4)/Params!$B$2,0) -> 0 | E19: =IFERROR(SUMIFS(tblPlannedAlloc[PlannedHoursAllocated],tblPlannedAlloc[Engineer],$A19,tblPlannedAlloc[Month],Months!$A$5)/Params!$B$2,0) -> 0 | F19: =IFERROR(SUMIFS(tblPlannedAlloc[PlannedHoursAllocated],tblPlannedAlloc[Engineer],$A19,tblPlannedAlloc[Month],Months!$A$6)/Params!$B$2,0) -> 0 | G19: =IFERROR(SUMIFS(tblPlannedAlloc[PlannedHoursAllocated],tblPlannedAlloc[Engineer],$A19,tblPlannedAlloc[Month],Months!$A$7)/Params!$B$2,0) -> 0 | H19: =IFERROR(SUMIFS(tblPlannedAlloc[PlannedHoursAllocated],tblPlannedAlloc[Engineer],$A19,tblPlannedAlloc[Month],Months!$A$8)/Params!$B$2,0) -> 0 | I19: =IFERROR(SUMIFS(tblPlannedAlloc[PlannedHoursAllocated],tblPlannedAlloc[Engineer],$A19,tblPlannedAlloc[Month],Months!$A$9)/Params!$B$2,0) -> 0 | J19: =IFERROR(SUMIFS(tblPlannedAlloc[PlannedHoursAllocated],tblPlannedAlloc[Engineer],$A19,tblPlannedAlloc[Month],Months!$A$10)/Params!$B$2,0) -> 0 | K19: =IFERROR(SUMIFS(tblPlannedAlloc[PlannedHoursAllocated],tblPlannedAlloc[Engineer],$A19,tblPlannedAlloc[Month],Months!$A$11)/Params!$B$2,0) -> 0 | L19: =IFERROR(SUMIFS(tblPlannedAlloc[PlannedHoursAllocated],tblPlannedAlloc[Engineer],$A19,tblPlannedAlloc[Month],Months!$A$12)/Params!$B$2,0) -> 0 | M19: =IFERROR(SUMIFS(tblPlannedAlloc[PlannedHoursAllocated],tblPlannedAlloc[Engineer],$A19,tblPlannedAlloc[Month],Months!$A$13)/Params!$B$2,0) -> 0
A20: Marcelo | B20: =IFERROR(SUMIFS(tblPlannedAlloc[PlannedHoursAllocated],tblPlannedAlloc[Engineer],$A20,tblPlannedAlloc[Month],Months!$A$2)/Params!$B$2,0) -> 1.0714286 | C20: =IFERROR(SUMIFS(tblPlannedAlloc[PlannedHoursAllocated],tblPlannedAlloc[Engineer],$A20,tblPlannedAlloc[Month],Months!$A$3)/Params!$B$2,0) -> 0 | D20: =IFERROR(SUMIFS(tblPlannedAlloc[PlannedHoursAllocated],tblPlannedAlloc[Engineer],$A20,tblPlannedAlloc[Month],Months!$A$4)/Params!$B$2,0) -> 0 | E20: =IFERROR(SUMIFS(tblPlannedAlloc[PlannedHoursAllocated],tblPlannedAlloc[Engineer],$A20,tblPlannedAlloc[Month],Months!$A$5)/Params!$B$2,0) -> 0 | F20: =IFERROR(SUMIFS(tblPlannedAlloc[PlannedHoursAllocated],tblPlannedAlloc[Engineer],$A20,tblPlannedAlloc[Month],Months!$A$6)/Params!$B$2,0) -> 0 | G20: =IFERROR(SUMIFS(tblPlannedAlloc[PlannedHoursAllocated],tblPlannedAlloc[Engineer],$A20,tblPlannedAlloc[Month],Months!$A$7)/Params!$B$2,0) -> 0 | H20: =IFERROR(SUMIFS(tblPlannedAlloc[PlannedHoursAllocated],tblPlannedAlloc[Engineer],$A20,tblPlannedAlloc[Month],Months!$A$8)/Params!$B$2,0) -> 0 | I20: =IFERROR(SUMIFS(tblPlannedAlloc[PlannedHoursAllocated],tblPlannedAlloc[Engineer],$A20,tblPlannedAlloc[Month],Months!$A$9)/Params!$B$2,0) -> 0 | J20: =IFERROR(SUMIFS(tblPlannedAlloc[PlannedHoursAllocated],tblPlannedAlloc[Engineer],$A20,tblPlannedAlloc[Month],Months!$A$10)/Params!$B$2,0) -> 0 | K20: =IFERROR(SUMIFS(tblPlannedAlloc[PlannedHoursAllocated],tblPlannedAlloc[Engineer],$A20,tblPlannedAlloc[Month],Months!$A$11)/Params!$B$2,0) -> 0 | L20: =IFERROR(SUMIFS(tblPlannedAlloc[PlannedHoursAllocated],tblPlannedAlloc[Engineer],$A20,tblPlannedAlloc[Month],Months!$A$12)/Params!$B$2,0) -> 0 | M20: =IFERROR(SUMIFS(tblPlannedAlloc[PlannedHoursAllocated],tblPlannedAlloc[Engineer],$A20,tblPlannedAlloc[Month],Months!$A$13)/Params!$B$2,0) -> 0
A21: Justin | B21: =IFERROR(SUMIFS(tblPlannedAlloc[PlannedHoursAllocated],tblPlannedAlloc[Engineer],$A21,tblPlannedAlloc[Month],Months!$A$2)/Params!$B$2,0) -> 0.92857143 | C21: =IFERROR(SUMIFS(tblPlannedAlloc[PlannedHoursAllocated],tblPlannedAlloc[Engineer],$A21,tblPlannedAlloc[Month],Months!$A$3)/Params!$B$2,0) -> 0 | D21: =IFERROR(SUMIFS(tblPlannedAlloc[PlannedHoursAllocated],tblPlannedAlloc[Engineer],$A21,tblPlannedAlloc[Month],Months!$A$4)/Params!$B$2,0) -> 0 | E21: =IFERROR(SUMIFS(tblPlannedAlloc[PlannedHoursAllocated],tblPlannedAlloc[Engineer],$A21,tblPlannedAlloc[Month],Months!$A$5)/Params!$B$2,0) -> 0 | F21: =IFERROR(SUMIFS(tblPlannedAlloc[PlannedHoursAllocated],tblPlannedAlloc[Engineer],$A21,tblPlannedAlloc[Month],Months!$A$6)/Params!$B$2,0) -> 0 | G21: =IFERROR(SUMIFS(tblPlannedAlloc[PlannedHoursAllocated],tblPlannedAlloc[Engineer],$A21,tblPlannedAlloc[Month],Months!$A$7)/Params!$B$2,0) -> 0 | H21: =IFERROR(SUMIFS(tblPlannedAlloc[PlannedHoursAllocated],tblPlannedAlloc[Engineer],$A21,tblPlannedAlloc[Month],Months!$A$8)/Params!$B$2,0) -> 0 | I21: =IFERROR(SUMIFS(tblPlannedAlloc[PlannedHoursAllocated],tblPlannedAlloc[Engineer],$A21,tblPlannedAlloc[Month],Months!$A$9)/Params!$B$2,0) -> 0 | J21: =IFERROR(SUMIFS(tblPlannedAlloc[PlannedHoursAllocated],tblPlannedAlloc[Engineer],$A21,tblPlannedAlloc[Month],Months!$A$10)/Params!$B$2,0) -> 0 | K21: =IFERROR(SUMIFS(tblPlannedAlloc[PlannedHoursAllocated],tblPlannedAlloc[Engineer],$A21,tblPlannedAlloc[Month],Months!$A$11)/Params!$B$2,0) -> 0 | L21: =IFERROR(SUMIFS(tblPlannedAlloc[PlannedHoursAllocated],tblPlannedAlloc[Engineer],$A21,tblPlannedAlloc[Month],Months!$A$12)/Params!$B$2,0) -> 0 | M21: =IFERROR(SUMIFS(tblPlannedAlloc[PlannedHoursAllocated],tblPlannedAlloc[Engineer],$A21,tblPlannedAlloc[Month],Months!$A$13)/Params!$B$2,0) -> 0
A22: Aaron | B22: =IFERROR(SUMIFS(tblPlannedAlloc[PlannedHoursAllocated],tblPlannedAlloc[Engineer],$A22,tblPlannedAlloc[Month],Months!$A$2)/Params!$B$2,0) -> 0.85714286 | C22: =IFERROR(SUMIFS(tblPlannedAlloc[PlannedHoursAllocated],tblPlannedAlloc[Engineer],$A22,tblPlannedAlloc[Month],Months!$A$3)/Params!$B$2,0) -> 0 | D22: =IFERROR(SUMIFS(tblPlannedAlloc[PlannedHoursAllocated],tblPlannedAlloc[Engineer],$A22,tblPlannedAlloc[Month],Months!$A$4)/Params!$B$2,0) -> 0 | E22: =IFERROR(SUMIFS(tblPlannedAlloc[PlannedHoursAllocated],tblPlannedAlloc[Engineer],$A22,tblPlannedAlloc[Month],Months!$A$5)/Params!$B$2,0) -> 0 | F22: =IFERROR(SUMIFS(tblPlannedAlloc[PlannedHoursAllocated],tblPlannedAlloc[Engineer],$A22,tblPlannedAlloc[Month],Months!$A$6)/Params!$B$2,0) -> 0 | G22: =IFERROR(SUMIFS(tblPlannedAlloc[PlannedHoursAllocated],tblPlannedAlloc[Engineer],$A22,tblPlannedAlloc[Month],Months!$A$7)/Params!$B$2,0) -> 0 | H22: =IFERROR(SUMIFS(tblPlannedAlloc[PlannedHoursAllocated],tblPlannedAlloc[Engineer],$A22,tblPlannedAlloc[Month],Months!$A$8)/Params!$B$2,0) -> 0 | I22: =IFERROR(SUMIFS(tblPlannedAlloc[PlannedHoursAllocated],tblPlannedAlloc[Engineer],$A22,tblPlannedAlloc[Month],Months!$A$9)/Params!$B$2,0) -> 0 | J22: =IFERROR(SUMIFS(tblPlannedAlloc[PlannedHoursAllocated],tblPlannedAlloc[Engineer],$A22,tblPlannedAlloc[Month],Months!$A$10)/Params!$B$2,0) -> 0 | K22: =IFERROR(SUMIFS(tblPlannedAlloc[PlannedHoursAllocated],tblPlannedAlloc[Engineer],$A22,tblPlannedAlloc[Month],Months!$A$11)/Params!$B$2,0) -> 0 | L22: =IFERROR(SUMIFS(tblPlannedAlloc[PlannedHoursAllocated],tblPlannedAlloc[Engineer],$A22,tblPlannedAlloc[Month],Months!$A$12)/Params!$B$2,0) -> 0 | M22: =IFERROR(SUMIFS(tblPlannedAlloc[PlannedHoursAllocated],tblPlannedAlloc[Engineer],$A22,tblPlannedAlloc[Month],Months!$A$13)/Params!$B$2,0) -> 0
A49: NPD Milestones Heat Map (Project x Milestone)
A51: Project | B51: DR1 | C51: DR2 | D51: DR3 | E51: Launch
A52: R1337.1 | B52: =IF(Milestones!B2="",NA(),Milestones!B2) -> #N/A | C52: =IF(Milestones!C2="",NA(),Milestones!C2) -> #N/A | D52: =IF(Milestones!D2="",NA(),Milestones!D2) -> #N/A | E52: =IF(Milestones!E2="",NA(),Milestones!E2) -> #N/A
A53: R1337.3 | B53: =IF(Milestones!B3="",NA(),Milestones!B3) -> #N/A | C53: =IF(Milestones!C3="",NA(),Milestones!C3) -> #N/A | D53: =IF(Milestones!D3="",NA(),Milestones!D3) -> #N/A | E53: =IF(Milestones!E3="",NA(),Milestones!E3) -> #N/A
A54: R1337.2 | B54: =IF(Milestones!B4="",NA(),Milestones!B4) -> #N/A | C54: =IF(Milestones!C4="",NA(),Milestones!C4) -> #N/A | D54: =IF(Milestones!D4="",NA(),Milestones!D4) -> #N/A | E54: =IF(Milestones!E4="",NA(),Milestones!E4) -> #N/A
A55: R1430.1A | B55: =IF(Milestones!B5="",NA(),Milestones!B5) -> #N/A | C55: =IF(Milestones!C5="",NA(),Milestones!C5) -> #N/A | D55: =IF(Milestones!D5="",NA(),Milestones!D5) -> #N/A | E55: =IF(Milestones!E5="",NA(),Milestones!E5) -> #N/A
A56: R1430.1B | B56: =IF(Milestones!B6="",NA(),Milestones!B6) -> #N/A | C56: =IF(Milestones!C6="",NA(),Milestones!C6) -> #N/A | D56: =IF(Milestones!D6="",NA(),Milestones!D6) -> #N/A | E56: =IF(Milestones!E6="",NA(),Milestones!E6) -> #N/A
A57: R1430.1C | B57: =IF(Milestones!B7="",NA(),Milestones!B7) -> #N/A | C57: =IF(Milestones!C7="",NA(),Milestones!C7) -> #N/A | D57: =IF(Milestones!D7="",NA(),Milestones!D7) -> #N/A | E57: =IF(Milestones!E7="",NA(),Milestones!E7) -> #N/A
A58: R1514.1 | B58: =IF(Milestones!B8="",NA(),Milestones!B8) -> #N/A | C58: =IF(Milestones!C8="",NA(),Milestones!C8) -> #N/A | D58: =IF(Milestones!D8="",NA(),Milestones!D8) -> #N/A | E58: =IF(Milestones!E8="",NA(),Milestones!E8) -> #N/A
A59: R1514.2 | B59: =IF(Milestones!B9="",NA(),Milestones!B9) -> #N/A | C59: =IF(Milestones!C9="",NA(),Milestones!C9) -> #N/A | D59: =IF(Milestones!D9="",NA(),Milestones!D9) -> #N/A | E59: =IF(Milestones!E9="",NA(),Milestones!E9) -> #N/A
A60: R1517 | B60: =IF(Milestones!B10="",NA(),Milestones!B10) -> #N/A | C60: =IF(Milestones!C10="",NA(),Milestones!C10) -> #N/A | D60: =IF(Milestones!D10="",NA(),Milestones!D10) -> #N/A | E60: =IF(Milestones!E10="",NA(),Milestones!E10) -> #N/A
A61: R1517.1 | B61: =IF(Milestones!B11="",NA(),Milestones!B11) -> #N/A | C61: =IF(Milestones!C11="",NA(),Milestones!C11) -> #N/A | D61: =IF(Milestones!D11="",NA(),Milestones!D11) -> #N/A | E61: =IF(Milestones!E11="",NA(),Milestones!E11) -> #N/A
A62: R1518 | B62: =IF(Milestones!B12="",NA(),Milestones!B12) -> 45692 | C62: =IF(Milestones!C12="",NA(),Milestones!C12) -> 45820 | D62: =IF(Milestones!D12="",NA(),Milestones!D12) -> 46094 | E62: =IF(Milestones!E12="",NA(),Milestones!E12) -> 46296
A63: R1527 | B63: =IF(Milestones!B13="",NA(),Milestones!B13) -> #N/A | C63: =IF(Milestones!C13="",NA(),Milestones!C13) -> #N/A | D63: =IF(Milestones!D13="",NA(),Milestones!D13) -> #N/A | E63: =IF(Milestones!E13="",NA(),Milestones!E13) -> #N/A
